Workbook

Sheet Dados_Brutos
A1: DATA INSPECAO | B1: OS | C1: CLUSTER | D1: TURBINA | E1: QTD IMAS TROCADOS | F1: DESCRICAO | G1: CICLO INSPECAO | H1: STATUS | I1: DATA SUBSTITUICAO | J1: K1DIAS PARADA | K1: DOWNWIND | L1: UPWIND | M1: OBSERVACOES | N1: PRIORIDADE
A2: 45384 | B2: 66159 | C2: Santo Inacio IV | D2: AEG-33 | E2: 80 | F2: Substituido | G2: Primeiro Ciclo | H2: Fora de Operação | I2: 45512 | J2: 128 | K2: Alto | L2: Alto | M2: Substituido os modulos 2 e 3 do circuito 3. Substituido o modulo 3 do circuito 2. Substituido as calhas dos circuittos 6, 7, 8, 9, 10, 11, 12, 13, 14. Substituido os Imãs das carreiras 10, 11, 17, 23, 57, 58, 77 e 84. | N2: =IF(Tabela1[[#This Row],[DATA INSPECAO]]="","",IF(AND($F2="Substituido",J2>0,),"ALTA PRIORIDADE","NORMAL")) -> NORMAL
A3: 45384 | B3: 66158 | C3: Garrote | D3: AEG-45 | E3: 80 | F3: Substituido | G3: Primeiro Ciclo | H3: Fora de Operação | I3: 45580 | J3: 196 | K3: Baixo | L3: Alto | M3: AEG parado, devido a problema de estufamento de imãs, como também realizado troca do modulo 04. | N3: =IF(Tabela1[[#This Row],[DATA INSPECAO]]="","",IF(AND($F3="Substituido",J3>0,),"ALTA PRIORIDADE","NORMAL")) -> NORMAL
A4: 45391 | B4: 66160 | C4: Santo Inacio III | D4: AEG-29 | E4: 142 | F4: Substituido | G4: Primeiro Ciclo | H4: Fora de Operação | I4: 45593 | J4: 202 | K4: Alto | L4: Baixo | M4: Em continuação das atividades: Realizado substituição de Spindle neste período, realizado substituição de 142 ímãs do Gerador. Identificamos 05 módulos do Gerador com necessidade de troca devido os danos causados pelo o estufamento dos ímãs e substituído o modulo 2 do circuito 5. Executado a correção dos módulos com danos superficiais. | N4: =IF(Tabela1[[#This Row],[DATA INSPECAO]]="","",IF(AND($F4="Substituido",J4>0,),"ALTA PRIORIDADE","NORMAL")) -> NORMAL
A5: 45408 | B5: 66434 | C5: Santo Inacio III | D5: AEG-06 | E5: 20 | F5: Substituido | G5: Primeiro Ciclo | H5: Fora de Operação | I5: 45519 | J5: 111 | K5: Alto | L5: Baixo | M5: Curto no Módulo estator circuito 05 do Gerador. Substituido o Modulo Nº 13, substituido as carreiras 35, 67. Por conta de outras falhas no conversor, a intervenção continuou na OS: 70554. | N5: =IF(Tabela1[[#This Row],[DATA INSPECAO]]="","",IF(AND($F5="Substituido",J5>0,),"ALTA PRIORIDADE","NORMAL")) -> NORMAL
A6: 45408 | B6: 66934 | C6: Garrote | D6: AEG-35 | E6: 200 | F6: Substituido | G6: Primeiro Ciclo | H6: Fora de Operação | I6: 45568 | J6: 160 | K6: Alto | L6: Alto | M6: Foi realizado a substituição dos Modulos 01 e 04, como também os Imãs das carreiras: 01, 02, 03, 04, 05, 06, 15, 17, 18, 19, 20, 30, 11, 114, 115, 116, 117, 118, 119, 120. A carreira 110, foi substituido por Imãs aproveitados de outras Máquinas. Calhas substituidas nas carreiras: 03, 04, 05, 15, 16, 17, 18, 19, 20. | N6: =IF(Tabela1[[#This Row],[DATA INSPECAO]]="","",IF(AND($F6="Substituido",J6>0,),"ALTA PRIORIDADE","NORMAL")) -> NORMAL
A7: 45415 | B7: 66933 | C7: Santo Inacio IV | D7: AEG-36 | E7: 260 | F7: Substituido | G7: Primeiro Ciclo | H7: Fora de Operação | I7: 45558 | J7: 143 | K7: Alto | L7: Baixo | M7: Inspeção nas carreiras de imãs e calhas danificadas,Calhas: 47, 64, 65, 67, 69, 70, 71, 74, 75, 76, 77, 81, 83, 84, 85, 86, 87, 88, 89, 90. Imãs danificados : 06, 47, 64, 65, 67, 69, 70, 71, 74, 75, 76, 77, 78, 81, 82, 83, 84, 85, 86, 87, 88, 89, 90, 91, 93, 110. Substituido os modulos 11. | N7: =IF(Tabela1[[#This Row],[DATA INSPECAO]]="","",IF(AND($F7="Substituido",J7>0,),"ALTA PRIORIDADE","NORMAL")) -> NORMAL
A8: 45420 | B8: 66931 | C8: São Raimundo | D8: AEG-16 | E8: 50 | F8: Substituido | G8: Primeiro Ciclo | H8: Fora de Operação | I8: 45478 | J8: 58 | K8: Alto | L8: Baixo | M8: Substituição dos Imãs das carreiras 18, 31, 59, 100 e 113. | N8: =IF(Tabela1[[#This Row],[DATA INSPECAO]]="","",IF(AND($F8="Substituido",J8>0,),"ALTA PRIORIDADE","NORMAL")) -> NORMAL
A9: 45421 | B9: - | C9: São Raimundo | D9: AEG-18 | E9: 0 | F9: Ímãs OK | G9: Primeiro Ciclo | H9: Em Operação | I9: - | J9: 0 | K9: Baixo | L9: Baixo | M9: Gerador lado downwind apresenta indicios iniciais de oxidação nos ímãs em todas as carreiras. | N9: =IF(Tabela1[[#This Row],[DATA INSPECAO]]="","",IF(AND($F9="Substituido",J9>0,),"ALTA PRIORIDADE","NORMAL")) -> NORMAL
A10: 45422 | B10: - | C10: Santo Inacio III | D10: AEG-31 | E10: 0 | F10: Ímãs OK | G10: Primeiro Ciclo | H10: Em Operação | I10: - | J10: 0 | K10: Baixo | L10: Médio | M10: Gerador lado downwind apresenta indicios iniciais de oxidação nos ímãs em todas as carreiras. Gerador lado upwind apresenta oxidação severa nas carreiras de ímãs 03, 31, 83 e com indicios de calha metalica de proteção do gerador levantada. porém o gabarito passa com facilidade. | N10: =IF(Tabela1[[#This Row],[DATA INSPECAO]]="","",IF(AND($F10="Substituido",J10>0,),"ALTA PRIORIDADE","NORMAL")) -> NORMAL
A11: 45425 | B11: 66932 | C11: Santo Inacio III | D11: AEG-05 | E11: 60 | F11: Substituido | G11: Primeiro Ciclo | H11: Fora de Operação | I11: 45597 | J11: 172 | K11: Alto | L11: Baixo | M11: Foi realizado a substituição dos Imãs das carreiras 14, 27, 94, 95, 96 e 99. Substituidos os modulos 9 e 7. Realizado a substituição de dois Fusiveis do gabinete U75. | N11: =IF(Tabela1[[#This Row],[DATA INSPECAO]]="","",IF(AND($F11="Substituido",J11>0,),"ALTA PRIORIDADE","NORMAL")) -> NORMAL
A12: 45429 | B12: 66935 | C12: Santo Inacio IV | D12: AEG-34 | E12: 60 | F12: Substituido | G12: Primeiro Ciclo | H12: Fora de Operação | I12: 45472 | J12: 43 | K12: Alto | L12: Alto | M12: Realizado a substituição dos Imãs das carreiras: 56, 57, 58, 61, 63, 64, como também aplicado resina no modulo 02 do circuito 01 que estava com dano na cabeceira. | N12: =IF(Tabela1[[#This Row],[DATA INSPECAO]]="","",IF(AND($F12="Substituido",J12>0,),"ALTA PRIORIDADE","NORMAL")) -> NORMAL
A13: 45432 | B13: - | C13: Garrote | D13: AEG-41 | E13: 0 | F13: Ímãs OK | G13: Primeiro Ciclo | H13: Em Operação | I13: - | J13: 0 | K13: Baixo | L13: Baixo | M13: Desplacamento de tinta na estrutura do gerador entre as carreiras 49 e 50 do lado downwind. Calha metalica de proteção do ímã da carreira 07 com pequenas avarias da região frontal. Gerador lado downwind apresenta indicios iniciais de oxidação nos ímãs em todas as carreiras. | N13: =IF(Tabela1[[#This Row],[DATA INSPECAO]]="","",IF(AND($F13="Substituido",J13>0,),"ALTA PRIORIDADE","NORMAL")) -> NORMAL
A14: 45433 | B14: 66887 | C14: Garrote | D14: AEG-46 | E14: 20 | F14: Substituido | G14: Primeiro Ciclo | H14: Fora de Operação | I14: 45457 | J14: 24 | K14: Alto | L14: Alto | M14: Carreiras 22 e 23 de ímãs não passou o gabarito de 04 mm no entre ferro do gerador. Calha metalica de proteção do ímã da carreira 45 com pequenas avarias da região frontal. | N14: =IF(Tabela1[[#This Row],[DATA INSPECAO]]="","",IF(AND($F14="Substituido",J14>0,),"ALTA PRIORIDADE","NORMAL")) -> NORMAL
A15: 45434 | B15: - | C15: Garrote | D15: AEG-47 | E15: 0 | F15: Ímãs OK | G15: Primeiro Ciclo | H15: Em Operação | I15: - | J15: 0 | K15: Baixo | L15: Baixo | M15: Gerador lado downwind apresenta indicios de oxidação nos ímãs de todas as carreiras. gabarito passa com facilidade. Gerador lado upwind apresenta indicios iniciais de oxidação em todas as carreiras de ímã. Calha metalica de proteção do ímã das carreiras 49 e 56 com pequenas avarias da região frontal | N15: =IF(Tabela1[[#This Row],[DATA INSPECAO]]="","",IF(AND($F15="Substituido",J15>0,),"ALTA PRIORIDADE","NORMAL")) -> NORMAL
A16: 45435 | B16: - | C16: Garrote | D16: AEG-14 | E16: 0 | F16: Ímãs OK | G16: Primeiro Ciclo | H16: Em Operação | I16: - | J16: 0 | K16: Baixo | L16: Baixo | M16: Calha metalica de proteção do ímã da carreira 113 com pequenas avarias da região frontal. Gerador lado downwind apresenta indicios iniciais de oxidação nos ímãs em todas as carreiras. | N16: =IF(Tabela1[[#This Row],[DATA INSPECAO]]="","",IF(AND($F16="Substituido",J16>0,),"ALTA PRIORIDADE","NORMAL")) -> NORMAL
A17: 45435 | B17: - | C17: Garrote | D17: AEG-43 | E17: 0 | F17: Ímãs OK | G17: Primeiro Ciclo | H17: Em Operação | I17: - | J17: 0 | K17: Baixo | L17: Baixo | M17: Calha metalica de proteção do ímã da carreira 20 com pequenas avarias da região frontal. Gerador lado downwind apresenta indicios iniciais de oxidação nos ímãs em todas as carreiras. Gerador lado upwind apresenta indicios iniciais de oxidação nos ímãs em todas as carreiras. | N17: =IF(Tabela1[[#This Row],[DATA INSPECAO]]="","",IF(AND($F17="Substituido",J17>0,),"ALTA PRIORIDADE","NORMAL")) -> NORMAL
A18: 45436 | B18: - | C18: Garrote | D18: AEG-04 | E18: 0 | F18: Ímãs OK | G18: Primeiro Ciclo | H18: Em Operação | I18: - | J18: 0 | K18: Baixo | L18: Baixo | M18: No relatorio de inspeção do primeiro ciclo, foi apontado avaria em todas as calhas na região frontal. Lado DownWind do gerador apresenta indicios de oxidação nos Imãs em todas as carreiras. | N18: =IF(Tabela1[[#This Row],[DATA INSPECAO]]="","",IF(AND($F18="Substituido",J18>0,),"ALTA PRIORIDADE","NORMAL")) -> NORMAL
A19: 45436 | B19: - | C19: Garrote | D19: AEG-39 | E19: 0 | F19: Ímãs OK | G19: Primeiro Ciclo | H19: Em Operação | I19: - | J19: 0 | K19: Médio | L19: Médio | M19: Houve dificuldade na inspeção devido o gabarito passar entre algumas calhas e outras não devido as emendas das calhas de proteção do estator não estarem totalmente uniforme. porém, gabarito passa na parte inferior de todas as calhas metalica de proteção do ímã. Gerador lado downwind apresenta oxidação em estagio avançado em todas as carreiras de ímã. Gerador lado upwind apresenta oxidação em estagio inicial em todas as carreiras de ímã. | N19: =IF(Tabela1[[#This Row],[DATA INSPECAO]]="","",IF(AND($F19="Substituido",J19>0,),"ALTA PRIORIDADE","NORMAL")) -> NORMAL
A20: 45439 | B20: - | C20: Garrote | D20: AEG-01 | E20: 0 | F20: Ímãs OK | G20: Primeiro Ciclo | H20: Em Operação | I20: - | J20: 0 | K20: Baixo | L20: Baixo | M20: No relatorio foi apontado que a calha frontal da carreira 102 estava com avaria na região frontal e com indicios iniciais de oxidação nos lados Upwind e DownWind. | N20: =IF(Tabela1[[#This Row],[DATA INSPECAO]]="","",IF(AND($F20="Substituido",J20>0,),"ALTA PRIORIDADE","NORMAL")) -> NORMAL
A21: 45439 | B21: - | C21: São Raimundo | D21: AEG-17 | E21: 0 | F21: Ímãs OK | G21: Primeiro Ciclo | H21: Em Operação | I21: - | J21: 0 | K21: Baixo | L21: Baixo | M21: Gerador lado upwind apresenta indicios iniciais de oxidação nos ímãs em todas as carreiras. Gerador lado downwind apresenta indicios iniciais de oxidação nos ímãs em todas as carreiras. | N21: =IF(Tabela1[[#This Row],[DATA INSPECAO]]="","",IF(AND($F21="Substituido",J21>0,),"ALTA PRIORIDADE","NORMAL")) -> NORMAL
A22: 45440 | B22: 67108 | C22: São Raimundo | D22: AEG-15 | E22: 50 | F22: Substituido | G22: Primeiro Ciclo | H22: Fora de Operação | I22: 45465 | J22: 25 | K22: Baixo | L22: Alto | M22: Encontrado estufamento de ímãs nas carreiras 03,31,33. Inicio de estufamento de ímãs nas carreiras 02,32. Gabarito passa com dificudade. Gerador lado dwind apresenta indicios iniciais de oxidação nos ímãs em todas as carreiras. Gerador lado upwind apresenta indicios iniciais de oxidação nos ímãs em todas as carreiras. | N22: =IF(Tabela1[[#This Row],[DATA INSPECAO]]="","",IF(AND($F22="Substituido",J22>0,),"ALTA PRIORIDADE","NORMAL")) -> NORMAL
A23: 45441 | B23: - | C23: São Raimundo | D23: AEG-08 | E23: 0 | F23: Ímãs OK | G23: Primeiro Ciclo | H23: Em Operação | I23: - | J23: 0 | K23: Baixo | L23: Baixo | M23: No relatorios de inspeção dos Imãs do gerador, foi apontado que os lados UpWind e DownWind apresentam oxidação em todas as carreiras de Imãs. | N23: =IF(Tabela1[[#This Row],[DATA INSPECAO]]="","",IF(AND($F23="Substituido",J23>0,),"ALTA PRIORIDADE","NORMAL")) -> NORMAL
A24: 45441 | B24: - | C24: São Raimundo | D24: AEG-19 | E24: 0 | F24: Ímãs OK | G24: Primeiro Ciclo | H24: Em Operação | I24: - | J24: 0 | K24: Baixo | L24: Baixo | M24: Gerador lado downwind apresenta indicios iniciais de oxidação nos ímãs em todas as carreiras | N24: =IF(Tabela1[[#This Row],[DATA INSPECAO]]="","",IF(AND($F24="Substituido",J24>0,),"ALTA PRIORIDADE","NORMAL")) -> NORMAL
A25: 45443 | B25: 67180 | C25: São Raimundo | D25: AEG-09 | E25: 20 | F25: Substituido | G25: Primeiro Ciclo | H25: Fora de Operação | I25: 45460 | J25: 17 | K25: Médio | L25: Baixo | M25: Encontrado estufamento de ímãs nas carreiras 60 e 100. Gerador lado downwind apresenta oxidação nos ímãs em todas as carreiras. Gerador lado upwind apresenta indicios iniciais de oxidação nos ímãs em todas as carreiras. | N25: =IF(Tabela1[[#This Row],[DATA INSPECAO]]="","",IF(AND($F25="Substituido",J25>0,),"ALTA PRIORIDADE","NORMAL")) -> NORMAL
A26: 45446 | B26: - | C26: São Raimundo | D26: AEG-10 | E26: 0 | F26: Ímãs OK | G26: Primeiro Ciclo | H26: Em Operação | I26: - | J26: 0 | K26: Baixo | L26: Baixo | M26: Gerador lado upwind apresenta indicios iniciais de oxidação nos ímãs em todas as carreiras.gerador lado downwind apresenta indicios iniciais de desfragmentação do imã n°01 de todas as carreiras. Gerador lado downwind apresenta oxidação avançada no ímã n°01 de todas as carreiras. | N26: =IF(Tabela1[[#This Row],[DATA INSPECAO]]="","",IF(AND($F26="Substituido",J26>0,),"ALTA PRIORIDADE","NORMAL")) -> NORMAL
A27: 45446 | B27: 67257 | C27: São Raimundo | D27: AEG-11 | E27: 20 | F27: Substituido | G27: Primeiro Ciclo | H27: Fora de Operação | I27: 45461 | J27: 15 | K27: Baixo | L27: Alto | M27: Encontrado estufamento de ímãs nas carreiras 06 e 07. Gerador lado DownWind apresenta inicios de oxidação nos ímãs em todas as carreiras. Gerador lado upwind apresenta indicios iniciais de oxidação nos ímãs em todas as carreiras. | N27: =IF(Tabela1[[#This Row],[DATA INSPECAO]]="","",IF(AND($F27="Substituido",J27>0,),"ALTA PRIORIDADE","NORMAL")) -> NORMAL
A28: 45447 | B28: - | C28: São Raimundo | D28: AEG-12 | E28: 0 | F28: Ímãs OK | G28: Primeiro Ciclo | H28: Em Operação | I28: - | J28: 0 | K28: Baixo | L28: Baixo | M28: Gerador lado upwind apresenta indicios iniciais de oxidação nos ímãs em todas as carreiras. Gerador lado downwind apresenta indicios iniciais de oxidação nos ímãs em todas as carreiras | N28: =IF(Tabela1[[#This Row],[DATA INSPECAO]]="","",IF(AND($F28="Substituido",J28>0,),"ALTA PRIORIDADE","NORMAL")) -> NORMAL
A29: 45447 | B29: 67315 | C29: São Raimundo | D29: AEG-13 | E29: 50 | F29: Substituido | G29: Primeiro Ciclo | H29: Fora de Operação | I29: 45468 | J29: 21 | K29: Baixo | L29: Alto | M29: Encontrado estufamento de ímãs nas carreiras 05, 07, 24 e 51. Encontrado inicio de estufamento de ímã na carreira 06, gabarito passa com dificudade. Gerador lado dwind apresenta indicios iniciais de oxidação nos ímãs em todas as carreiras. Gerador lado upwind apresenta indicios iniciais de oxidação nos ímãs em todas as carreiras. Gerador lado upwind apresenta indicios iniciais de desfragmentação do imã n°10 das carreiras 45, 46, 64, 63. | N29: =IF(Tabela1[[#This Row],[DATA INSPECAO]]="","",IF(AND($F29="Substituido",J29>0,),"ALTA PRIORIDADE","NORMAL")) -> NORMAL
A30: 45448 | B30: 67373 | C30: Santo Inacio III | D30: AEG-24 | E30: 30 | F30: Substituido | G30: Primeiro Ciclo | H30: Fora de Operação | I30: 45463 | J30: 15 | K30: Baixo | L30: Alto | M30: Gerador lado upwind apresenta oxidação severa em todas as carreira nos ímãs em todas as carreiras. Gerador lado downwind apresenta oxidação severa nos ímãs em todas as carreiras encontrado estufamento de ímãs nas carreiras 02, 52 e 118 de ímãs. | N30: =IF(Tabela1[[#This Row],[DATA INSPECAO]]="","",IF(AND($F30="Substituido",J30>0,),"ALTA PRIORIDADE","NORMAL")) -> NORMAL
A31: 45448 | B31: 67395 | C31: Santo Inacio III | D31: AEG-26 | E31: 10 | F31: Substituido | G31: Primeiro Ciclo | H31: Fora de Operação | I31: 45458 | J31: 10 | K31: Baixo | L31: Alto | M31: Encontrado estufamento de ímãs na carreira 01. Gerador lado dwind apresenta indicios iniciais de oxidação nos ímãs em todas as carreiras. Gerador lado upwind apresenta indicios iniciais de oxidação nos ímãs em todas as carreiras. Calhas metalica de proteção de ímã com deformação mecanica no lado upwind. Calha metalica de proteção de imã da carreira 15 com avaria na parte frontal. | N31: =IF(Tabela1[[#This Row],[DATA INSPECAO]]="","",IF(AND($F31="Substituido",J31>0,),"ALTA PRIORIDADE","NORMAL")) -> NORMAL
A32: 45449 | B32: - | C32: Santo Inacio III | D32: AEG-20 | E32: 0 | F32: Ímãs OK | G32: Primeiro Ciclo | H32: Em Operação | I32: - | J32: 0 | K32: Baixo | L32: Baixo | M32: Gerador lado downwind apresenta indicios iniciais de oxidação nos ímãs em todas as carreiras. Gerador lado upwind apresenta indicios iniciais de oxidação nos ímãs em todas as carreiras. | N32: =IF(Tabela1[[#This Row],[DATA INSPECAO]]="","",IF(AND($F32="Substituido",J32>0,),"ALTA PRIORIDADE","NORMAL")) -> NORMAL
A33: 45449 | B33: - | C33: Santo Inacio III | D33: AEG-27 | E33: 0 | F33: Ímãs OK | G33: Primeiro Ciclo | H33: Em Operação | I33: - | J33: 0 | K33: Médio | L33: Médio | M33: Gerador lado upwind apresenta oxidação nos ímãs em todas as carreiras. Gerador lado downwind apresenta oxidação severa nos ímãs em todas as carreiras | N33: =IF(Tabela1[[#This Row],[DATA INSPECAO]]="","",IF(AND($F33="Substituido",J33>0,),"ALTA PRIORIDADE","NORMAL")) -> NORMAL
A34: 45450 | B34: - | C34: Santo Inacio III | D34: AEG-21 | E34: 0 | F34: Ímãs OK | G34: Primeiro Ciclo | H34: Em Operação | I34: - | J34: 0 | K34: Baixo | L34: Baixo | M34: Gerador lado downwind apresenta indicios iniciais de oxidação nos ímãs em todas as carreiras. Gerador lado upwind apresenta indicios iniciais de oxidação nos ímãs em todas as carreiras. Calha de proteção de ímã com avaria na parte frontal nas carreiras 44 e 45. | N34: =IF(Tabela1[[#This Row],[DATA INSPECAO]]="","",IF(AND($F34="Substituido",J34>0,),"ALTA PRIORIDADE","NORMAL")) -> NORMAL
A35: 45450 | B35: - | C35: Santo Inacio III | D35: AEG-23 | E35: 0 | F35: Ímãs OK | G35: Primeiro Ciclo | H35: Em Operação | I35: - | J35: 0 | K35: Médio | L35: Médio | M35: Gerador lado upwind apresenta oxidação nos ímãs em todas as carreiras. Gerador lado downwind apresenta oxidação nos ímãs em todas as carreiras | N35: =IF(Tabela1[[#This Row],[DATA INSPECAO]]="","",IF(AND($F35="Substituido",J35>0,),"ALTA PRIORIDADE","NORMAL")) -> NORMAL
A36: 45453 | B36: 67613 | C36: Santo Inacio III | D36: AEG-07 | E36: 30 | F36: Substituido | G36: Primeiro Ciclo | H36: Fora de Operação | I36: 45469 | J36: 16 | K36: Baixo | L36: Alto | M36: Gerador lado UpWind apresenta indicios iniciais de oxidação nos ímãs em todas as carreiras. Gerador lado downwind apresenta oxidação severa nos ímãs em todas as carreiras 05, 33 e 120 de ímãs, não passou no gabarito de 04 mm no entre ferro do gerador. | N36: =IF(Tabela1[[#This Row],[DATA INSPECAO]]="","",IF(AND($F36="Substituido",J36>0,),"ALTA PRIORIDADE","NORMAL")) -> NORMAL
A37: 45454 | B37: - | C37: Santo Inacio IV | D37: AEG-37 | E37: 0 | F37: Ímãs OK | G37: Primeiro Ciclo | H37: Em Operação | I37: - | J37: 0 | K37: Médio | L37: Baixo | M37: Gerador lado upwind apresenta indicios iniciais de oxidação nos ímãs em todas as carreiras. Gerador lado downwind apresenta oxidação nos ímãs em todas as carreiras. | N37: =IF(Tabela1[[#This Row],[DATA INSPECAO]]="","",IF(AND($F37="Substituido",J37>0,),"ALTA PRIORIDADE","NORMAL")) -> NORMAL
A38: 45454 | B38: 67656 | C38: Garrote | D38: AEG-44 | E38: 20 | F38: Substituido | G38: Primeiro Ciclo | H38: Fora de Operação | I38: 45462 | J38: 8 | K38: Alto | L38: Alto | M38: Durante inspeção de rotina para avaliar os ímãs/entreferro no Gerador, em especial nas carreiras 103 e 104. Foi constatado estufamento de ímã nacarreira 103 e 104. Após substituição dos Imãs a turbina foi colocada em operção. | N38: =IF(Tabela1[[#This Row],[DATA INSPECAO]]="","",IF(AND($F38="Substituido",J38>0,),"ALTA PRIORIDADE","NORMAL")) -> NORMAL
A39: 45455 | B39: - | C39: Santo Inacio IV | D39: AEG-40 | E39: 0 | F39: Ímãs OK | G39: Primeiro Ciclo | H39: Em Operação | I39: - | J39: 0 | K39: Médio | L39: Baixo | M39: Gerador lado upwind apresenta indicios iniciais de oxidação nos ímãs em todas as carreiras. Gerador lado downwind apresenta oxidação nos ímãs em todas as carreiras. | N39: =IF(Tabela1[[#This Row],[DATA INSPECAO]]="","",IF(AND($F39="Substituido",J39>0,),"ALTA PRIORIDADE","NORMAL")) -> NORMAL
A40: 45456 | B40: - | C40: Santo Inacio IV | D40: AEG-02 | E40: 0 | F40: Ímãs OK | G40: Primeiro Ciclo | H40: Em Operação | I40: - | J40: 0 | K40: Baixo | L40: Baixo | M40: Gerador lado DownWind e UpWind apresenta indicios iniciais de oxidação nos ímãs em todas as carreiras. 13/06/2024 | N40: =IF(Tabela1[[#This Row],[DATA INSPECAO]]="","",IF(AND($F40="Substituido",J40>0,),"ALTA PRIORIDADE","NORMAL")) -> NORMAL
...

Sheet Dados_Brutos (Agregados)
A1: Data | B1: OS | C1: AEG | D1: Total_Imas | E1: Carreiras | F1: Classificação_Port | G1: Classificação_StarPort | H1: Classificação_Geral

Sheet Resumo_Turbinas
A1: TURBINA | B1: CLUSTER | C1: TOTAL IMAS TROCADOS | D1: PRIMEIRA INSPECAO | E1: ULTIMA INSPECAO | F1: STATUS ATUAL | G1: DIAS PARADA ACUMULADOS | H1: OXIDACAO BAIXA | I1: OXIDACAO MEDIA | J1: OXIDACAO ALTA | K1: NIVEL RISCO | L1: CUSTO ESTIMADO | M1: MTBF DIAS | N1: MTTR DIAS | O1: PROXIMA MANUTENCAO | P1: INDICE -PERFORMANCE
A2: AEG-01 | B2: =IF(Tabela2[[#This Row],[ TURBINA]]="","",_xlfn.XLOOKUP(Tabela2[[#This Row],[ TURBINA]],Tabela1[TURBINA],Tabela1[CLUSTER])) -> Garrote | C2: =IF(Tabela2[[#This Row],[ TURBINA]]="","",SUMIF(Dados_Brutos!D:D,A2,Dados_Brutos!E:E)) -> 0 | D2: {=IF(Tabela2[[#This Row],[ TURBINA]]="","",MIN(IF(Dados_Brutos!D:D=Tabela2[[#This Row],[ TURBINA]],Dados_Brutos!A:A)))} -> 45439 | E2: {=IF(Tabela2[[#This Row],[ TURBINA]]="","",MAX(IF(Tabela1[TURBINA] =Tabela2[[#This Row],[ TURBINA]],Tabela1[DATA INSPECAO])))} -> 45775 | F2: =IFERROR(INDEX(Dados_Brutos!H:H,MATCH(A2,Dados_Brutos!D:D,0)),"") -> Em Operação | G2: =IF(Tabela2[[#This Row],[ TURBINA]]="","",SUMIF(Dados_Brutos!D:D,A2,Dados_Brutos!J:J)) -> 0 | H2: =IF(Tabela2[[#This Row],[ TURBINA]]="","",COUNTIFS(Dados_Brutos!D:D,A2,Dados_Brutos!K:K,"*Baixo*")) -> 3 | I2: =IF(Tabela2[[#This Row],[ TURBINA]]="","",COUNTIFS(Dados_Brutos!D:D,A2,Dados_Brutos!K:K,"*Médio*")) -> 0 | J2: =IF(Tabela2[[#This Row],[ TURBINA]]="","",COUNTIFS(Dados_Brutos!D:D,A2,Dados_Brutos!K:K,"*Alto*")) -> 0 | K2: =IF(Tabela2[[#This Row],[ TURBINA]]="","",IF(AND(C2>20,J2>3),"🟥 ALTO RISCO",IF(AND(C2>10,I2>1),"🟨 MÉDIO RISCO","🟩 BAIXO RISCO"))) -> 🟩 BAIXO RISCO | L2: =Tabela2[[#This Row],[ TOTAL IMAS TROCADOS]]*Config!$B$2 -> 0 | M2: =IF(C2>0, (TODAY()-D2)/C2, "Sem dados") -> Sem dados | N2: =IF(C2>0, G2/C2, "Sem dados") -> Sem dados | O2: =IFERROR(DATE(YEAR(E2),MONTH(E2)+7,DAY(E2)),"") -> 45989 | P2: =IFERROR(1-(G2/(TODAY()-D2)),"") -> 1
A3: AEG-02 | B3: =IF(Tabela2[[#This Row],[ TURBINA]]="","",_xlfn.XLOOKUP(Tabela2[[#This Row],[ TURBINA]],Tabela1[TURBINA],Tabela1[CLUSTER])) -> Santo Inacio IV | C3: =IF(Tabela2[[#This Row],[ TURBINA]]="","",SUMIF(Dados_Brutos!D:D,A3,Dados_Brutos!E:E)) -> 0 | D3: {=IF(Tabela2[[#This Row],[ TURBINA]]="","",MIN(IF(Dados_Brutos!D:D=Tabela2[[#This Row],[ TURBINA]],Dados_Brutos!A:A)))} -> 45456 | E3: {=IF(Tabela2[[#This Row],[ TURBINA]]="","",MAX(IF(Tabela1[TURBINA] =Tabela2[[#This Row],[ TURBINA]],Tabela1[DATA INSPECAO])))} -> 45639 | F3: =IFERROR(INDEX(Dados_Brutos!H:H,MATCH(A3,Dados_Brutos!D:D,0)),"") -> Em Operação | G3: =IF(Tabela2[[#This Row],[ TURBINA]]="","",SUMIF(Dados_Brutos!D:D,A3,Dados_Brutos!J:J)) -> 0 | H3: =IF(Tabela2[[#This Row],[ TURBINA]]="","",COUNTIFS(Dados_Brutos!D:D,A3,Dados_Brutos!K:K,"*Baixo*")) -> 3 | I3: =IF(Tabela2[[#This Row],[ TURBINA]]="","",COUNTIFS(Dados_Brutos!D:D,A3,Dados_Brutos!K:K,"*Médio*")) -> 0 | J3: =IF(Tabela2[[#This Row],[ TURBINA]]="","",COUNTIFS(Dados_Brutos!D:D,A3,Dados_Brutos!K:K,"*Alto*")) -> 0 | K3: =IF(Tabela2[[#This Row],[ TURBINA]]="","",IF(AND(C3>20,J3>3),"🟥 ALTO RISCO",IF(AND(C3>10,I3>1),"🟨 MÉDIO RISCO","🟩 BAIXO RISCO"))) -> 🟩 BAIXO RISCO | L3: =Tabela2[[#This Row],[ TOTAL IMAS TROCADOS]]*Config!$B$2 -> 0 | M3: =IF(C3>0, (TODAY()-D3)/C3, "Sem dados") -> Sem dados | N3: =IF(C3>0, G3/C3, "Sem dados") -> Sem dados | O3: =IFERROR(DATE(YEAR(E3),MONTH(E3)+7,DAY(E3)),"") -> 45851 | P3: =IFERROR(1-(G3/(TODAY()-D3)),"") -> 1
A4: AEG-03 | B4: =IF(Tabela2[[#This Row],[ TURBINA]]="","",_xlfn.XLOOKUP(Tabela2[[#This Row],[ TURBINA]],Tabela1[TURBINA],Tabela1[CLUSTER])) -> Santo Inacio IV | C4: =IF(Tabela2[[#This Row],[ TURBINA]]="","",SUMIF(Dados_Brutos!D:D,A4,Dados_Brutos!E:E)) -> 0 | D4: {=IF(Tabela2[[#This Row],[ TURBINA]]="","",MIN(IF(Dados_Brutos!D:D=Tabela2[[#This Row],[ TURBINA]],Dados_Brutos!A:A)))} -> 45462 | E4: {=IF(Tabela2[[#This Row],[ TURBINA]]="","",MAX(IF(Tabela1[TURBINA] =Tabela2[[#This Row],[ TURBINA]],Tabela1[DATA INSPECAO])))} -> 45644 | F4: =IFERROR(INDEX(Dados_Brutos!H:H,MATCH(A4,Dados_Brutos!D:D,0)),"") -> Em Operação | G4: =IF(Tabela2[[#This Row],[ TURBINA]]="","",SUMIF(Dados_Brutos!D:D,A4,Dados_Brutos!J:J)) -> 0 | H4: =IF(Tabela2[[#This Row],[ TURBINA]]="","",COUNTIFS(Dados_Brutos!D:D,A4,Dados_Brutos!K:K,"*Baixo*")) -> 3 | I4: =IF(Tabela2[[#This Row],[ TURBINA]]="","",COUNTIFS(Dados_Brutos!D:D,A4,Dados_Brutos!K:K,"*Médio*")) -> 0 | J4: =IF(Tabela2[[#This Row],[ TURBINA]]="","",COUNTIFS(Dados_Brutos!D:D,A4,Dados_Brutos!K:K,"*Alto*")) -> 0 | K4: =IF(Tabela2[[#This Row],[ TURBINA]]="","",IF(AND(C4>20,J4>3),"🟥 ALTO RISCO",IF(AND(C4>10,I4>1),"🟨 MÉDIO RISCO","🟩 BAIXO RISCO"))) -> 🟩 BAIXO RISCO | L4: =Tabela2[[#This Row],[ TOTAL IMAS TROCADOS]]*Config!$B$2 -> 0 | M4: =IF(C4>0, (TODAY()-D4)/C4, "Sem dados") -> Sem dados | N4: =IF(C4>0, G4/C4, "Sem dados") -> Sem dados | O4: =IFERROR(DATE(YEAR(E4),MONTH(E4)+7,DAY(E4)),"") -> 45856 | P4: =IFERROR(1-(G4/(TODAY()-D4)),"") -> 1
A5: AEG-04 | B5: =IF(Tabela2[[#This Row],[ TURBINA]]="","",_xlfn.XLOOKUP(Tabela2[[#This Row],[ TURBINA]],Tabela1[TURBINA],Tabela1[CLUSTER])) -> Garrote | C5: =IF(Tabela2[[#This Row],[ TURBINA]]="","",SUMIF(Dados_Brutos!D:D,A5,Dados_Brutos!E:E)) -> 0 | D5: {=IF(Tabela2[[#This Row],[ TURBINA]]="","",MIN(IF(Dados_Brutos!D:D=Tabela2[[#This Row],[ TURBINA]],Dados_Brutos!A:A)))} -> 45436 | E5: {=IF(Tabela2[[#This Row],[ TURBINA]]="","",MAX(IF(Tabela1[TURBINA] =Tabela2[[#This Row],[ TURBINA]],Tabela1[DATA INSPECAO])))} -> 45734 | F5: =IFERROR(INDEX(Dados_Brutos!H:H,MATCH(A5,Dados_Brutos!D:D,0)),"") -> Em Operação | G5: =IF(Tabela2[[#This Row],[ TURBINA]]="","",SUMIF(Dados_Brutos!D:D,A5,Dados_Brutos!J:J)) -> 0 | H5: =IF(Tabela2[[#This Row],[ TURBINA]]="","",COUNTIFS(Dados_Brutos!D:D,A5,Dados_Brutos!K:K,"*Baixo*")) -> 3 | I5: =IF(Tabela2[[#This Row],[ TURBINA]]="","",COUNTIFS(Dados_Brutos!D:D,A5,Dados_Brutos!K:K,"*Médio*")) -> 0 | J5: =IF(Tabela2[[#This Row],[ TURBINA]]="","",COUNTIFS(Dados_Brutos!D:D,A5,Dados_Brutos!K:K,"*Alto*")) -> 0 | K5: =IF(Tabela2[[#This Row],[ TURBINA]]="","",IF(AND(C5>20,J5>3),"🟥 ALTO RISCO",IF(AND(C5>10,I5>1),"🟨 MÉDIO RISCO","🟩 BAIXO RISCO"))) -> 🟩 BAIXO RISCO | L5: =Tabela2[[#This Row],[ TOTAL IMAS TROCADOS]]*Config!$B$2 -> 0 | M5: =IF(C5>0, (TODAY()-D5)/C5, "Sem dados") -> Sem dados | N5: =IF(C5>0, G5/C5, "Sem dados") -> Sem dados | O5: =IFERROR(DATE(YEAR(E5),MONTH(E5)+7,DAY(E5)),"") -> 45948 | P5: =IFERROR(1-(G5/(TODAY()-D5)),"") -> 1
A6: AEG-05 | B6: =IF(Tabela2[[#This Row],[ TURBINA]]="","",_xlfn.XLOOKUP(Tabela2[[#This Row],[ TURBINA]],Tabela1[TURBINA],Tabela1[CLUSTER])) -> Santo Inacio III | C6: =IF(Tabela2[[#This Row],[ TURBINA]]="","",SUMIF(Dados_Brutos!D:D,A6,Dados_Brutos!E:E)) -> 80 | D6: {=IF(Tabela2[[#This Row],[ TURBINA]]="","",MIN(IF(Dados_Brutos!D:D=Tabela2[[#This Row],[ TURBINA]],Dados_Brutos!A:A)))} -> 45425 | E6: {=IF(Tabela2[[#This Row],[ TURBINA]]="","",MAX(IF(Tabela1[TURBINA] =Tabela2[[#This Row],[ TURBINA]],Tabela1[DATA INSPECAO])))} -> 45749 | F6: =IFERROR(INDEX(Dados_Brutos!H:H,MATCH(A6,Dados_Brutos!D:D,0)),"") -> Fora de Operação | G6: =IF(Tabela2[[#This Row],[ TURBINA]]="","",SUMIF(Dados_Brutos!D:D,A6,Dados_Brutos!J:J)) -> 173 | H6: =IF(Tabela2[[#This Row],[ TURBINA]]="","",COUNTIFS(Dados_Brutos!D:D,A6,Dados_Brutos!K:K,"*Baixo*")) -> 2 | I6: =IF(Tabela2[[#This Row],[ TURBINA]]="","",COUNTIFS(Dados_Brutos!D:D,A6,Dados_Brutos!K:K,"*Médio*")) -> 0 | J6: =IF(Tabela2[[#This Row],[ TURBINA]]="","",COUNTIFS(Dados_Brutos!D:D,A6,Dados_Brutos!K:K,"*Alto*")) -> 1 | K6: =IF(Tabela2[[#This Row],[ TURBINA]]="","",IF(AND(C6>20,J6>3),"🟥 ALTO RISCO",IF(AND(C6>10,I6>1),"🟨 MÉDIO RISCO","🟩 BAIXO RISCO"))) -> 🟩 BAIXO RISCO | L6: =Tabela2[[#This Row],[ TOTAL IMAS TROCADOS]]*Config!$B$2 -> 102575.58 | M6: =IF(C6>0, (TODAY()-D6)/C6, "Sem dados") -> 6.8625 | N6: =IF(C6>0, G6/C6, "Sem dados") -> 2.1625 | O6: =IFERROR(DATE(YEAR(E6),MONTH(E6)+7,DAY(E6)),"") -> 45963 | P6: =IFERROR(1-(G6/(TODAY()-D6)),"") -> 0.6848816
A7: AEG-06 | B7: =IF(Tabela2[[#This Row],[ TURBINA]]="","",_xlfn.XLOOKUP(Tabela2[[#This Row],[ TURBINA]],Tabela1[TURBINA],Tabela1[CLUSTER])) -> Santo Inacio III | C7: =IF(Tabela2[[#This Row],[ TURBINA]]="","",SUMIF(Dados_Brutos!D:D,A7,Dados_Brutos!E:E)) -> 20 | D7: {=IF(Tabela2[[#This Row],[ TURBINA]]="","",MIN(IF(Dados_Brutos!D:D=Tabela2[[#This Row],[ TURBINA]],Dados_Brutos!A:A)))} -> 45408 | E7: {=IF(Tabela2[[#This Row],[ TURBINA]]="","",MAX(IF(Tabela1[TURBINA] =Tabela2[[#This Row],[ TURBINA]],Tabela1[DATA INSPECAO])))} -> 45624 | F7: =IFERROR(INDEX(Dados_Brutos!H:H,MATCH(A7,Dados_Brutos!D:D,0)),"") -> Fora de Operação | G7: =IF(Tabela2[[#This Row],[ TURBINA]]="","",SUMIF(Dados_Brutos!D:D,A7,Dados_Brutos!J:J)) -> 111 | H7: =IF(Tabela2[[#This Row],[ TURBINA]]="","",COUNTIFS(Dados_Brutos!D:D,A7,Dados_Brutos!K:K,"*Baixo*")) -> 2 | I7: =IF(Tabela2[[#This Row],[ TURBINA]]="","",COUNTIFS(Dados_Brutos!D:D,A7,Dados_Brutos!K:K,"*Médio*")) -> 0 | J7: =IF(Tabela2[[#This Row],[ TURBINA]]="","",COUNTIFS(Dados_Brutos!D:D,A7,Dados_Brutos!K:K,"*Alto*")) -> 1 | K7: =IF(Tabela2[[#This Row],[ TURBINA]]="","",IF(AND(C7>20,J7>3),"🟥 ALTO RISCO",IF(AND(C7>10,I7>1),"🟨 MÉDIO RISCO","🟩 BAIXO RISCO"))) -> 🟩 BAIXO RISCO | L7: =Tabela2[[#This Row],[ TOTAL IMAS TROCADOS]]*Config!$B$2 -> 25643.896 | M7: =IF(C7>0, (TODAY()-D7)/C7, "Sem dados") -> 28.3 | N7: =IF(C7>0, G7/C7, "Sem dados") -> 5.55 | O7: =IFERROR(DATE(YEAR(E7),MONTH(E7)+7,DAY(E7)),"") -> 45836 | P7: =IFERROR(1-(G7/(TODAY()-D7)),"") -> 0.80388693
A8: AEG-07 | B8: =IF(Tabela2[[#This Row],[ TURBINA]]="","",_xlfn.XLOOKUP(Tabela2[[#This Row],[ TURBINA]],Tabela1[TURBINA],Tabela1[CLUSTER])) -> Santo Inacio III | C8: =IF(Tabela2[[#This Row],[ TURBINA]]="","",SUMIF(Dados_Brutos!D:D,A8,Dados_Brutos!E:E)) -> 30 | D8: {=IF(Tabela2[[#This Row],[ TURBINA]]="","",MIN(IF(Dados_Brutos!D:D=Tabela2[[#This Row],[ TURBINA]],Dados_Brutos!A:A)))} -> 45453 | E8: {=IF(Tabela2[[#This Row],[ TURBINA]]="","",MAX(IF(Tabela1[TURBINA] =Tabela2[[#This Row],[ TURBINA]],Tabela1[DATA INSPECAO])))} -> 45624 | F8: =IFERROR(INDEX(Dados_Brutos!H:H,MATCH(A8,Dados_Brutos!D:D,0)),"") -> Fora de Operação | G8: =IF(Tabela2[[#This Row],[ TURBINA]]="","",SUMIF(Dados_Brutos!D:D,A8,Dados_Brutos!J:J)) -> 16 | H8: =IF(Tabela2[[#This Row],[ TURBINA]]="","",COUNTIFS(Dados_Brutos!D:D,A8,Dados_Brutos!K:K,"*Baixo*")) -> 3 | I8: =IF(Tabela2[[#This Row],[ TURBINA]]="","",COUNTIFS(Dados_Brutos!D:D,A8,Dados_Brutos!K:K,"*Médio*")) -> 0 | J8: =IF(Tabela2[[#This Row],[ TURBINA]]="","",COUNTIFS(Dados_Brutos!D:D,A8,Dados_Brutos!K:K,"*Alto*")) -> 0 | K8: =IF(Tabela2[[#This Row],[ TURBINA]]="","",IF(AND(C8>20,J8>3),"🟥 ALTO RISCO",IF(AND(C8>10,I8>1),"🟨 MÉDIO RISCO","🟩 BAIXO RISCO"))) -> 🟩 BAIXO RISCO | L8: =Tabela2[[#This Row],[ TOTAL IMAS TROCADOS]]*Config!$B$2 -> 38465.844 | M8: =IF(C8>0, (TODAY()-D8)/C8, "Sem dados") -> 17.366667 | N8: =IF(C8>0, G8/C8, "Sem dados") -> 0.53333333 | O8: =IFERROR(DATE(YEAR(E8),MONTH(E8)+7,DAY(E8)),"") -> 45836 | P8: =IFERROR(1-(G8/(TODAY()-D8)),"") -> 0.96928983
A9: AEG-08 | B9: =IF(Tabela2[[#This Row],[ TURBINA]]="","",_xlfn.XLOOKUP(Tabela2[[#This Row],[ TURBINA]],Tabela1[TURBINA],Tabela1[CLUSTER])) -> São Raimundo | C9: =IF(Tabela2[[#This Row],[ TURBINA]]="","",SUMIF(Dados_Brutos!D:D,A9,Dados_Brutos!E:E)) -> 3 | D9: {=IF(Tabela2[[#This Row],[ TURBINA]]="","",MIN(IF(Dados_Brutos!D:D=Tabela2[[#This Row],[ TURBINA]],Dados_Brutos!A:A)))} -> 45441 | E9: {=IF(Tabela2[[#This Row],[ TURBINA]]="","",MAX(IF(Tabela1[TURBINA] =Tabela2[[#This Row],[ TURBINA]],Tabela1[DATA INSPECAO])))} -> 45784 | F9: =IFERROR(INDEX(Dados_Brutos!H:H,MATCH(A9,Dados_Brutos!D:D,0)),"") -> Em Operação | G9: =IF(Tabela2[[#This Row],[ TURBINA]]="","",SUMIF(Dados_Brutos!D:D,A9,Dados_Brutos!J:J)) -> 35 | H9: =IF(Tabela2[[#This Row],[ TURBINA]]="","",COUNTIFS(Dados_Brutos!D:D,A9,Dados_Brutos!K:K,"*Baixo*")) -> 3 | I9: =IF(Tabela2[[#This Row],[ TURBINA]]="","",COUNTIFS(Dados_Brutos!D:D,A9,Dados_Brutos!K:K,"*Médio*")) -> 1 | J9: =IF(Tabela2[[#This Row],[ TURBINA]]="","",COUNTIFS(Dados_Brutos!D:D,A9,Dados_Brutos!K:K,"*Alto*")) -> 0 | K9: =IF(Tabela2[[#This Row],[ TURBINA]]="","",IF(AND(C9>20,J9>3),"🟥 ALTO RISCO",IF(AND(C9>10,I9>1),"🟨 MÉDIO RISCO","🟩 BAIXO RISCO"))) -> 🟩 BAIXO RISCO | L9: =Tabela2[[#This Row],[ TOTAL IMAS TROCADOS]]*Config!$B$2 -> 3846.5844 | M9: =IF(C9>0, (TODAY()-D9)/C9, "Sem dados") -> 177.66667 | N9: =IF(C9>0, G9/C9, "Sem dados") -> 11.666667 | O9: =IFERROR(DATE(YEAR(E9),MONTH(E9)+7,DAY(E9)),"") -> 45998 | P9: =IFERROR(1-(G9/(TODAY()-D9)),"") -> 0.93433396
A10: AEG-09 | B10: =IF(Tabela2[[#This Row],[ TURBINA]]="","",_xlfn.XLOOKUP(Tabela2[[#This Row],[ TURBINA]],Tabela1[TURBINA],Tabela1[CLUSTER])) -> São Raimundo | C10: =IF(Tabela2[[#This Row],[ TURBINA]]="","",SUMIF(Dados_Brutos!D:D,A10,Dados_Brutos!E:E)) -> 21 | D10: {=IF(Tabela2[[#This Row],[ TURBINA]]="","",MIN(IF(Dados_Brutos!D:D=Tabela2[[#This Row],[ TURBINA]],Dados_Brutos!A:A)))} -> 45443 | E10: {=IF(Tabela2[[#This Row],[ TURBINA]]="","",MAX(IF(Tabela1[TURBINA] =Tabela2[[#This Row],[ TURBINA]],Tabela1[DATA INSPECAO])))} -> 45862 | F10: =IFERROR(INDEX(Dados_Brutos!H:H,MATCH(A10,Dados_Brutos!D:D,0)),"") -> Fora de Operação | G10: =IF(Tabela2[[#This Row],[ TURBINA]]="","",SUMIF(Dados_Brutos!D:D,A10,Dados_Brutos!J:J)) -> 33 | H10: =IF(Tabela2[[#This Row],[ TURBINA]]="","",COUNTIFS(Dados_Brutos!D:D,A10,Dados_Brutos!K:K,"*Baixo*")) -> 3 | I10: =IF(Tabela2[[#This Row],[ TURBINA]]="","",COUNTIFS(Dados_Brutos!D:D,A10,Dados_Brutos!K:K,"*Médio*")) -> 1 | J10: =IF(Tabela2[[#This Row],[ TURBINA]]="","",COUNTIFS(Dados_Brutos!D:D,A10,Dados_Brutos!K:K,"*Alto*")) -> 0 | K10: =IF(Tabela2[[#This Row],[ TURBINA]]="","",IF(AND(C10>20,J10>3),"🟥 ALTO RISCO",IF(AND(C10>10,I10>1),"🟨 MÉDIO RISCO","🟩 BAIXO RISCO"))) -> 🟩 BAIXO RISCO | L10: =Tabela2[[#This Row],[ TOTAL IMAS TROCADOS]]*Config!$B$2 -> 26926.091 | M10: =IF(C10>0, (TODAY()-D10)/C10, "Sem dados") -> 25.285714 | N10: =IF(C10>0, G10/C10, "Sem dados") -> 1.5714286 | O10: =IFERROR(DATE(YEAR(E10),MONTH(E10)+7,DAY(E10)),"") -> 46077 | P10: =IFERROR(1-(G10/(TODAY()-D10)),"") -> 0.93785311
A11: AEG-10 | B11: =IF(Tabela2[[#This Row],[ TURBINA]]="","",_xlfn.XLOOKUP(Tabela2[[#This Row],[ TURBINA]],Tabela1[TURBINA],Tabela1[CLUSTER])) -> São Raimundo | C11: =IF(Tabela2[[#This Row],[ TURBINA]]="","",SUMIF(Dados_Brutos!D:D,A11,Dados_Brutos!E:E)) -> 0 | D11: {=IF(Tabela2[[#This Row],[ TURBINA]]="","",MIN(IF(Dados_Brutos!D:D=Tabela2[[#This Row],[ TURBINA]],Dados_Brutos!A:A)))} -> 45446 | E11: {=IF(Tabela2[[#This Row],[ TURBINA]]="","",MAX(IF(Tabela1[TURBINA] =Tabela2[[#This Row],[ TURBINA]],Tabela1[DATA INSPECAO])))} -> 45624 | F11: =IFERROR(INDEX(Dados_Brutos!H:H,MATCH(A11,Dados_Brutos!D:D,0)),"") -> Em Operação | G11: =IF(Tabela2[[#This Row],[ TURBINA]]="","",SUMIF(Dados_Brutos!D:D,A11,Dados_Brutos!J:J)) -> 0 | H11: =IF(Tabela2[[#This Row],[ TURBINA]]="","",COUNTIFS(Dados_Brutos!D:D,A11,Dados_Brutos!K:K,"*Baixo*")) -> 3 | I11: =IF(Tabela2[[#This Row],[ TURBINA]]="","",COUNTIFS(Dados_Brutos!D:D,A11,Dados_Brutos!K:K,"*Médio*")) -> 0 | J11: =IF(Tabela2[[#This Row],[ TURBINA]]="","",COUNTIFS(Dados_Brutos!D:D,A11,Dados_Brutos!K:K,"*Alto*")) -> 0 | K11: =IF(Tabela2[[#This Row],[ TURBINA]]="","",IF(AND(C11>20,J11>3),"🟥 ALTO RISCO",IF(AND(C11>10,I11>1),"🟨 MÉDIO RISCO","🟩 BAIXO RISCO"))) -> 🟩 BAIXO RISCO | L11: =Tabela2[[#This Row],[ TOTAL IMAS TROCADOS]]*Config!$B$2 -> 0 | M11: =IF(C11>0, (TODAY()-D11)/C11, "Sem dados") -> Sem dados | N11: =IF(C11>0, G11/C11, "Sem dados") -> Sem dados | O11: =IFERROR(DATE(YEAR(E11),MONTH(E11)+7,DAY(E11)),"") -> 45836 | P11: =IFERROR(1-(G11/(TODAY()-D11)),"") -> 1
A12: AEG-11 | B12: =IF(Tabela2[[#This Row],[ TURBINA]]="","",_xlfn.XLOOKUP(Tabela2[[#This Row],[ TURBINA]],Tabela1[TURBINA],Tabela1[CLUSTER])) -> São Raimundo | C12: =IF(Tabela2[[#This Row],[ TURBINA]]="","",SUMIF(Dados_Brutos!D:D,A12,Dados_Brutos!E:E)) -> 20 | D12: {=IF(Tabela2[[#This Row],[ TURBINA]]="","",MIN(IF(Dados_Brutos!D:D=Tabela2[[#This Row],[ TURBINA]],Dados_Brutos!A:A)))} -> 45446 | E12: {=IF(Tabela2[[#This Row],[ TURBINA]]="","",MAX(IF(Tabela1[TURBINA] =Tabela2[[#This Row],[ TURBINA]],Tabela1[DATA INSPECAO])))} -> 45789 | F12: =IFERROR(INDEX(Dados_Brutos!H:H,MATCH(A12,Dados_Brutos!D:D,0)),"") -> Fora de Operação | G12: =IF(Tabela2[[#This Row],[ TURBINA]]="","",SUMIF(Dados_Brutos!D:D,A12,Dados_Brutos!J:J)) -> 15 | H12: =IF(Tabela2[[#This Row],[ TURBINA]]="","",COUNTIFS(Dados_Brutos!D:D,A12,Dados_Brutos!K:K,"*Baixo*")) -> 3 | I12: =IF(Tabela2[[#This Row],[ TURBINA]]="","",COUNTIFS(Dados_Brutos!D:D,A12,Dados_Brutos!K:K,"*Médio*")) -> 0 | J12: =IF(Tabela2[[#This Row],[ TURBINA]]="","",COUNTIFS(Dados_Brutos!D:D,A12,Dados_Brutos!K:K,"*Alto*")) -> 0 | K12: =IF(Tabela2[[#This Row],[ TURBINA]]="","",IF(AND(C12>20,J12>3),"🟥 ALTO RISCO",IF(AND(C12>10,I12>1),"🟨 MÉDIO RISCO","🟩 BAIXO RISCO"))) -> 🟩 BAIXO RISCO | L12: =Tabela2[[#This Row],[ TOTAL IMAS TROCADOS]]*Config!$B$2 -> 25643.896 | M12: =IF(C12>0, (TODAY()-D12)/C12, "Sem dados") -> 26.4 | N12: =IF(C12>0, G12/C12, "Sem dados") -> 0.75 | O12: =IFERROR(DATE(YEAR(E12),MONTH(E12)+7,DAY(E12)),"") -> 46003 | P12: =IFERROR(1-(G12/(TODAY()-D12)),"") -> 0.97159091
A13: AEG-12 | B13: =IF(Tabela2[[#This Row],[ TURBINA]]="","",_xlfn.XLOOKUP(Tabela2[[#This Row],[ TURBINA]],Tabela1[TURBINA],Tabela1[CLUSTER])) -> São Raimundo | C13: =IF(Tabela2[[#This Row],[ TURBINA]]="","",SUMIF(Dados_Brutos!D:D,A13,Dados_Brutos!E:E)) -> 0 | D13: {=IF(Tabela2[[#This Row],[ TURBINA]]="","",MIN(IF(Dados_Brutos!D:D=Tabela2[[#This Row],[ TURBINA]],Dados_Brutos!A:A)))} -> 45447 | E13: {=IF(Tabela2[[#This Row],[ TURBINA]]="","",MAX(IF(Tabela1[TURBINA] =Tabela2[[#This Row],[ TURBINA]],Tabela1[DATA INSPECAO])))} -> 45790 | F13: =IFERROR(INDEX(Dados_Brutos!H:H,MATCH(A13,Dados_Brutos!D:D,0)),"") -> Em Operação | G13: =IF(Tabela2[[#This Row],[ TURBINA]]="","",SUMIF(Dados_Brutos!D:D,A13,Dados_Brutos!J:J)) -> 0 | H13: =IF(Tabela2[[#This Row],[ TURBINA]]="","",COUNTIFS(Dados_Brutos!D:D,A13,Dados_Brutos!K:K,"*Baixo*")) -> 3 | I13: =IF(Tabela2[[#This Row],[ TURBINA]]="","",COUNTIFS(Dados_Brutos!D:D,A13,Dados_Brutos!K:K,"*Médio*")) -> 0 | J13: =IF(Tabela2[[#This Row],[ TURBINA]]="","",COUNTIFS(Dados_Brutos!D:D,A13,Dados_Brutos!K:K,"*Alto*")) -> 0 | K13: =IF(Tabela2[[#This Row],[ TURBINA]]="","",IF(AND(C13>20,J13>3),"🟥 ALTO RISCO",IF(AND(C13>10,I13>1),"🟨 MÉDIO RISCO","🟩 BAIXO RISCO"))) -> 🟩 BAIXO RISCO | L13: =Tabela2[[#This Row],[ TOTAL IMAS TROCADOS]]*Config!$B$2 -> 0 | M13: =IF(C13>0, (TODAY()-D13)/C13, "Sem dados") -> Sem dados | N13: =IF(C13>0, G13/C13, "Sem dados") -> Sem dados | O13: =IFERROR(DATE(YEAR(E13),MONTH(E13)+7,DAY(E13)),"") -> 46004 | P13: =IFERROR(1-(G13/(TODAY()-D13)),"") -> 1
... A48: AEG-47 | B48: =IF(Tabela2[[#This Row],[ TURBINA]]="","",_xlfn.XLOOKUP(Tabela2[[#This Row],[ TURBINA]],Tabela1[TURBINA],Tabela1[CLUSTER])) -> Garrote | C48: =IF(Tabela2[[#This Row],[ TURBINA]]="","",SUMIF(Dados_Brutos!D:D,A48,Dados_Brutos!E:E)) -> 0 | D48: {=IF(Tabela2[[#This Row],[ TURBINA]]="","",MIN(IF(Dados_Brutos!D:D=Tabela2[[#This Row],[ TURBINA]],Dados_Brutos!A:A)))} -> 45434 | E48: {=IF(Tabela2[[#This Row],[ TURBINA]]="","",MAX(IF(Tabela1[TURBINA] =Tabela2[[#This Row],[ TURBINA]],Tabela1[DATA INSPECAO])))} -> 45756 | F48: =IFERROR(INDEX(Dados_Brutos!H:H,MATCH(A48,Dados_Brutos!D:D,0)),"") -> Em Operação | G48: =IF(Tabela2[[#This Row],[ TURBINA]]="","",SUMIF(Dados_Brutos!D:D,A48,Dados_Brutos!J:J)) -> 0 | H48: =IF(Tabela2[[#This Row],[ TURBINA]]="","",COUNTIFS(Dados_Brutos!D:D,A48,Dados_Brutos!K:K,"*Baixo*")) -> 3 | I48: =IF(Tabela2[[#This Row],[ TURBINA]]="","",COUNTIFS(Dados_Brutos!D:D,A48,Dados_Brutos!K:K,"*Médio*")) -> 0 | J48: =IF(Tabela2[[#This Row],[ TURBINA]]="","",COUNTIFS(Dados_Brutos!D:D,A48,Dados_Brutos!K:K,"*Alto*")) -> 0 | K48: =IF(Tabela2[[#This Row],[ TURBINA]]="","",IF(AND(C48>20,J48>3),"🟥 ALTO RISCO",IF(AND(C48>10,I48>1),"🟨 MÉDIO RISCO","🟩 BAIXO RISCO"))) -> 🟩 BAIXO RISCO | L48: =Tabela2[[#This Row],[ TOTAL IMAS TROCADOS]]*Config!$B$2 -> 0 | M48: =IF(C48>0, (TODAY()-D48)/C48, "Sem dados") -> Sem dados | N48: =IF(C48>0, G48/C48, "Sem dados") -> Sem dados | O48: =IFERROR(DATE(YEAR(E48),MONTH(E48)+7,DAY(E48)),"") -> 45970 | P48: =IFERROR(1-(G48/(TODAY()-D48)),"") -> 1

Sheet Analise_Ciclos
A1: CICLO | B1: ANO | C1: TURBINAS INSPECIONADAS | D1: TURBINAS COM SUBSTITUICAO | E1: TURBINAS PARADAS | F1: IMAS TROCADOS TOTAL | G1: OXIDACAO BAIXA | H1: OXIDACAO MEDIA | I1: OXIDACAO ALTA | J1: CUSTO TOTAL
A2: Primeiro Ciclo | B2: =IF(A2="Primeiro Ciclo", 2024, IF(A2="Segundo Ciclo", 2024, 2025)) -> 2024 | C2: =COUNTIF(Dados_Brutos!G:G,A2) -> 46 | D2: =COUNTIFS(Dados_Brutos!$G:$G,$A2,Dados_Brutos!$F:$F,"Substituido") -> 20 | E2: =COUNTIFS(Dados_Brutos!$G:$G,$A2,Dados_Brutos!$H:$H,"Fora de Operação") -> 19 | F2: =SUMIF(Dados_Brutos!G:G,A2,Dados_Brutos!E:E) -> 1262 | G2: =COUNTIFS(Dados_Brutos!G:G,A2,Dados_Brutos!K:K,"*Baixo*") -> 29 | H2: =COUNTIFS(Dados_Brutos!G:G,A2,Dados_Brutos!K:K,"*Médio*") -> 6 | I2: =COUNTIFS(Dados_Brutos!G:G,A2,Dados_Brutos!K:K,"*Alto*") -> 11 | J2: =F2*Config!$B$2 -> 1618129.8
A3: Segundo Ciclo | B3: =IF(A3="Primeiro Ciclo", 2024, IF(A3="Segundo Ciclo", 2024, 2025)) -> 2024 | C3: =COUNTIF(Dados_Brutos!G:G,A3) -> 47 | D3: =COUNTIFS(Dados_Brutos!$G:$G,$A3,Dados_Brutos!$F:$F,"Substituido") -> 6 | E3: =COUNTIFS(Dados_Brutos!$G:$G,$A3,Dados_Brutos!$H:$H,"Fora de Operação") -> 1 | F3: =SUMIF(Dados_Brutos!G:G,A3,Dados_Brutos!E:E) -> 80 | G3: =COUNTIFS(Dados_Brutos!G:G,A3,Dados_Brutos!K:K,"*Baixo*") -> 40 | H3: =COUNTIFS(Dados_Brutos!G:G,A3,Dados_Brutos!K:K,"*Médio*") -> 7 | I3: =COUNTIFS(Dados_Brutos!G:G,A3,Dados_Brutos!K:K,"*Alto*") -> 0 | J3: =F3*Config!$B$2 -> 102575.58
A4: Terceiro Ciclo | B4: =IF(A4="Primeiro Ciclo", 2024, IF(A4="Segundo Ciclo", 2024, 2025)) -> 2025 | C4: =COUNTIF(Dados_Brutos!G:G,A4) -> 47 | D4: =COUNTIFS(Dados_Brutos!$G:$G,$A4,Dados_Brutos!$F:$F,"Substituido") -> 6 | E4: =COUNTIFS(Dados_Brutos!$G:$G,$A4,Dados_Brutos!$H:$H,"Fora de Operação") -> 4 | F4: =SUMIF(Dados_Brutos!G:G,A4,Dados_Brutos!E:E) -> 340 | G4: =COUNTIFS(Dados_Brutos!G:G,A4,Dados_Brutos!K:K,"*Baixo*") -> 39 | H4: =COUNTIFS(Dados_Brutos!G:G,A4,Dados_Brutos!K:K,"*Médio*") -> 7 | I4: =COUNTIFS(Dados_Brutos!G:G,A4,Dados_Brutos!K:K,"*Alto*") -> 1 | J4: =F4*Config!$B$2 -> 435946.23
A5: Troca de Spindle | B5: =IF(A5="Primeiro Ciclo", 2024, IF(A5="Segundo Ciclo", 2024, 2025)) -> 2025 | C5: =COUNTIF(Dados_Brutos!G:G,A5) -> 6 | D5: =COUNTIFS(Dados_Brutos!$G:$G,$A5,Dados_Brutos!$F:$F,"Substituido") -> 6 | E5: =COUNTIFS(Dados_Brutos!$G:$G,$A5,Dados_Brutos!$H:$H,"Fora de Operação") -> 6 | F5: =SUMIF(Dados_Brutos!G:G,A5,Dados_Brutos!E:E) -> 44 | G5: =COUNTIFS(Dados_Brutos!G:G,A5,Dados_Brutos!K:K,"*Baixo*") -> 5 | H5: =COUNTIFS(Dados_Brutos!G:G,A5,Dados_Brutos!K:K,"*Médio*") -> 0 | I5: =COUNTIFS(Dados_Brutos!G:G,A5,Dados_Brutos!K:K,"*Alto*") -> 1 | J5: =F5*Config!$B$2 -> 56416.571
A6: Quarto Ciclo | B6: =IF(A6="Primeiro Ciclo", 2024, IF(A6="Segundo Ciclo", 2024, 2025)) -> 2025 | C6: =COUNTIF(Dados_Brutos!G:G,A6) -> 5 | D6: =COUNTIFS(Dados_Brutos!$G:$G,$A6,Dados_Brutos!$F:$F,"Substituido") -> 3 | E6: =COUNTIFS(Dados_Brutos!$G:$G,$A6,Dados_Brutos!$H:$H,"Fora de Operação") -> 1 | F6: =SUMIF(Dados_Brutos!G:G,A6,Dados_Brutos!E:E) -> 40 | G6: =COUNTIFS(Dados_Brutos!G:G,A6,Dados_Brutos!K:K,"*Baixo*") -> 5 | H6: =COUNTIFS(Dados_Brutos!G:G,A6,Dados_Brutos!K:K,"*Médio*") -> 0 | I6: =COUNTIFS(Dados_Brutos!G:G,A6,Dados_Brutos!K:K,"*Alto*") -> 0 | J6: =F6*Config!$B$2 -> 51287.792

Sheet Evolução_Mensal
A1: MES ANO | B1: IMAS TROCADOS | C1: TURBINAS PARADAS | D1: OXIDACAO BAIXA | E1: OXIDACAO MEDIA | F1: OXIDACAO ALTA | G1: CUSTO TOTAL | H1: MTBF MES | I1: MTTR MES | J1: OEE MES
A2: 45457 | B2: =SUMIFS(Dados_Brutos!E:E,Dados_Brutos!A:A,">="&DATE(2024,1,1),Dados_Brutos!A:A,"<="&DATE(2025,12,1)) -> 1766 | C2: =COUNTIFS(Dados_Brutos!A:A,">="&DATE(2024,1,1),Dados_Brutos!A:A,"<="&DATE(2025,12,31),Dados_Brutos!H:H,"Fora de Operação") -> 31 | D2: =COUNTIFS(Dados_Brutos!A:A,">="&$A2,Dados_Brutos!A:A,"<="&EOMONTH($A2,0),Dados_Brutos!K:K,"*Baixo*") -> 5 | E2: =COUNTIFS(Dados_Brutos!A:A,">="&$A2,Dados_Brutos!A:A,"<="&EOMONTH($A2,0),Dados_Brutos!K:K,"*Médio*") -> 0 | F2: =COUNTIFS(Dados_Brutos!A:A,">="&$A2,Dados_Brutos!A:A,"<="&EOMONTH($A2,0),Dados_Brutos!K:K,"*Alto*") -> 1 | G2: =B2*Config!$B$2 -> 2264356 | H2: =IF(B2>0, 30/B2, "Sem dados") -> 0.016987542 | I2: =IFERROR(AVERAGEIFS(Dados_Brutos!J:J, Dados_Brutos!A:A, ">="&A2, Dados_Brutos!A:A, "<="&EOMONTH(A2,0)),"-") -> 1.8333333 | J2: =(1-(SUMIFS(Dados_Brutos!J:J,Dados_Brutos!A:A,">="&DATE(2024,1,1),Dados_Brutos!A:A,"<="&DATE(2025,12,31))/(47*24*30))) -> 0.95537825
A3: 45458 | B3: =SUMIFS(Dados_Brutos!E:E,Dados_Brutos!A:A,">="&DATE(2024,1,1),Dados_Brutos!A:A,"<="&DATE(2025,12,1)) -> 1766 | C3: =COUNTIFS(Dados_Brutos!A:A,">="&DATE(2024,1,1),Dados_Brutos!A:A,"<="&DATE(2025,12,31),Dados_Brutos!H:H,"Fora de Operação") -> 31 | D3: =COUNTIFS(Dados_Brutos!A:A,">="&$A3,Dados_Brutos!A:A,"<="&EOMONTH($A3,0),Dados_Brutos!K:K,"*Baixo*") -> 4 | E3: =COUNTIFS(Dados_Brutos!A:A,">="&$A3,Dados_Brutos!A:A,"<="&EOMONTH($A3,0),Dados_Brutos!K:K,"*Médio*") -> 0 | F3: =COUNTIFS(Dados_Brutos!A:A,">="&$A3,Dados_Brutos!A:A,"<="&EOMONTH($A3,0),Dados_Brutos!K:K,"*Alto*") -> 1 | G3: =B3*Config!$B$2 -> 2264356 | H3: =IF(B3>0, 30/B3, "Sem dados") -> 0.016987542 | I3: =IFERROR(AVERAGEIFS(Dados_Brutos!J:J, Dados_Brutos!A:A, ">="&A3, Dados_Brutos!A:A, "<="&EOMONTH(A3,0)),"-") -> 2.2 | J3: =(1-(SUMIFS(Dados_Brutos!J:J,Dados_Brutos!A:A,">="&DATE(2024,1,1),Dados_Brutos!A:A,"<="&DATE(2025,12,31))/(47*24*30))) -> 0.95537825
A4: 45460 | B4: =SUMIFS(Dados_Brutos!E:E,Dados_Brutos!A:A,">="&DATE(2024,1,1),Dados_Brutos!A:A,"<="&DATE(2025,12,1)) -> 1766 | C4: =COUNTIFS(Dados_Brutos!A:A,">="&DATE(2024,1,1),Dados_Brutos!A:A,"<="&DATE(2025,12,31),Dados_Brutos!H:H,"Fora de Operação") -> 31 | D4: =COUNTIFS(Dados_Brutos!A:A,">="&$A4,Dados_Brutos!A:A,"<="&EOMONTH($A4,0),Dados_Brutos!K:K,"*Baixo*") -> 4 | E4: =COUNTIFS(Dados_Brutos!A:A,">="&$A4,Dados_Brutos!A:A,"<="&EOMONTH($A4,0),Dados_Brutos!K:K,"*Médio*") -> 0 | F4: =COUNTIFS(Dados_Brutos!A:A,">="&$A4,Dados_Brutos!A:A,"<="&EOMONTH($A4,0),Dados_Brutos!K:K,"*Alto*") -> 1 | G4: =B4*Config!$B$2 -> 2264356 | H4: =IF(B4>0, 30/B4, "Sem dados") -> 0.016987542 | I4: =IFERROR(AVERAGEIFS(Dados_Brutos!J:J, Dados_Brutos!A:A, ">="&A4, Dados_Brutos!A:A, "<="&EOMONTH(A4,0)),"-") -> 2.2 | J4: =(1-(SUMIFS(Dados_Brutos!J:J,Dados_Brutos!A:A,">="&DATE(2024,1,1),Dados_Brutos!A:A,"<="&DATE(2025,12,31))/(47*24*30))) -> 0.95537825
A5: 45461 | B5: =SUMIFS(Dados_Brutos!E:E,Dados_Brutos!A:A,">="&DATE(2024,1,1),Dados_Brutos!A:A,"<="&DATE(2025,12,1)) -> 1766 | C5: =COUNTIFS(Dados_Brutos!A:A,">="&DATE(2024,1,1),Dados_Brutos!A:A,"<="&DATE(2025,12,31),Dados_Brutos!H:H,"Fora de Operação") -> 31 | D5: =COUNTIFS(Dados_Brutos!A:A,">="&$A5,Dados_Brutos!A:A,"<="&EOMONTH($A5,0),Dados_Brutos!K:K,"*Baixo*") -> 3 | E5: =COUNTIFS(Dados_Brutos!A:A,">="&$A5,Dados_Brutos!A:A,"<="&EOMONTH($A5,0),Dados_Brutos!K:K,"*Médio*") -> 0 | F5: =COUNTIFS(Dados_Brutos!A:A,">="&$A5,Dados_Brutos!A:A,"<="&EOMONTH($A5,0),Dados_Brutos!K:K,"*Alto*") -> 1 | G5: =B5*Config!$B$2 -> 2264356 | H5: =IF(B5>0, 30/B5, "Sem dados") -> 0.016987542 | I5: =IFERROR(AVERAGEIFS(Dados_Brutos!J:J, Dados_Brutos!A:A, ">="&A5, Dados_Brutos!A:A, "<="&EOMONTH(A5,0)),"-") -> 2.75 | J5: =(1-(SUMIFS(Dados_Brutos!J:J,Dados_Brutos!A:A,">="&DATE(2024,1,1),Dados_Brutos!A:A,"<="&DATE(2025,12,31))/(47*24*30))) -> 0.95537825
A6: 45462 | B6: =SUMIFS(Dados_Brutos!E:E,Dados_Brutos!A:A,">="&DATE(2024,1,1),Dados_Brutos!A:A,"<="&DATE(2025,12,1)) -> 1766 | C6: =COUNTIFS(Dados_Brutos!A:A,">="&DATE(2024,1,1),Dados_Brutos!A:A,"<="&DATE(2025,12,31),Dados_Brutos!H:H,"Fora de Operação") -> 31 | D6: =COUNTIFS(Dados_Brutos!A:A,">="&$A6,Dados_Brutos!A:A,"<="&EOMONTH($A6,0),Dados_Brutos!K:K,"*Baixo*") -> 2 | E6: =COUNTIFS(Dados_Brutos!A:A,">="&$A6,Dados_Brutos!A:A,"<="&EOMONTH($A6,0),Dados_Brutos!K:K,"*Médio*") -> 0 | F6: =COUNTIFS(Dados_Brutos!A:A,">="&$A6,Dados_Brutos!A:A,"<="&EOMONTH($A6,0),Dados_Brutos!K:K,"*Alto*") -> 1 | G6: =B6*Config!$B$2 -> 2264356 | H6: =IF(B6>0, 30/B6, "Sem dados") -> 0.016987542 | I6: =IFERROR(AVERAGEIFS(Dados_Brutos!J:J, Dados_Brutos!A:A, ">="&A6, Dados_Brutos!A:A, "<="&EOMONTH(A6,0)),"-") -> 3.6666667 | J6: =(1-(SUMIFS(Dados_Brutos!J:J,Dados_Brutos!A:A,">="&DATE(2024,1,1),Dados_Brutos!A:A,"<="&DATE(2025,12,31))/(47*24*30))) -> 0.95537825
A7: 45463 | B7: =SUMIFS(Dados_Brutos!E:E,Dados_Brutos!A:A,">="&DATE(2024,1,1),Dados_Brutos!A:A,"<="&DATE(2025,12,1)) -> 1766 | C7: =COUNTIFS(Dados_Brutos!A:A,">="&DATE(2024,1,1),Dados_Brutos!A:A,"<="&DATE(2025,12,31),Dados_Brutos!H:H,"Fora de Operação") -> 31 | D7: =COUNTIFS(Dados_Brutos!A:A,">="&$A7,Dados_Brutos!A:A,"<="&EOMONTH($A7,0),Dados_Brutos!K:K,"*Baixo*") -> 1 | E7: =COUNTIFS(Dados_Brutos!A:A,">="&$A7,Dados_Brutos!A:A,"<="&EOMONTH($A7,0),Dados_Brutos!K:K,"*Médio*") -> 0 | F7: =COUNTIFS(Dados_Brutos!A:A,">="&$A7,Dados_Brutos!A:A,"<="&EOMONTH($A7,0),Dados_Brutos!K:K,"*Alto*") -> 1 | G7: =B7*Config!$B$2 -> 2264356 | H7: =IF(B7>0, 30/B7, "Sem dados") -> 0.016987542 | I7: =IFERROR(AVERAGEIFS(Dados_Brutos!J:J, Dados_Brutos!A:A, ">="&A7, Dados_Brutos!A:A, "<="&EOMONTH(A7,0)),"-") -> 5.5 | J7: =(1-(SUMIFS(Dados_Brutos!J:J,Dados_Brutos!A:A,">="&DATE(2024,1,1),Dados_Brutos!A:A,"<="&DATE(2025,12,31))/(47*24*30))) -> 0.95537825
A8: 45465 | B8: =SUMIFS(Dados_Brutos!E:E,Dados_Brutos!A:A,">="&DATE(2024,1,1),Dados_Brutos!A:A,"<="&DATE(2025,12,1)) -> 1766 | C8: =COUNTIFS(Dados_Brutos!A:A,">="&DATE(2024,1,1),Dados_Brutos!A:A,"<="&DATE(2025,12,31),Dados_Brutos!H:H,"Fora de Operação") -> 31 | D8: =COUNTIFS(Dados_Brutos!A:A,">="&$A8,Dados_Brutos!A:A,"<="&EOMONTH($A8,0),Dados_Brutos!K:K,"*Baixo*") -> 0 | E8: =COUNTIFS(Dados_Brutos!A:A,">="&$A8,Dados_Brutos!A:A,"<="&EOMONTH($A8,0),Dados_Brutos!K:K,"*Médio*") -> 0 | F8: =COUNTIFS(Dados_Brutos!A:A,">="&$A8,Dados_Brutos!A:A,"<="&EOMONTH($A8,0),Dados_Brutos!K:K,"*Alto*") -> 0 | G8: =B8*Config!$B$2 -> 2264356 | H8: =IF(B8>0, 30/B8, "Sem dados") -> 0.016987542 | I8: =IFERROR(AVERAGEIFS(Dados_Brutos!J:J, Dados_Brutos!A:A, ">="&A8, Dados_Brutos!A:A, "<="&EOMONTH(A8,0)),"-") -> - | J8: =(1-(SUMIFS(Dados_Brutos!J:J,Dados_Brutos!A:A,">="&DATE(2024,1,1),Dados_Brutos!A:A,"<="&DATE(2025,12,31))/(47*24*30))) -> 0.95537825
A9: 45468 | B9: =SUMIFS(Dados_Brutos!E:E,Dados_Brutos!A:A,">="&DATE(2024,1,1),Dados_Brutos!A:A,"<="&DATE(2025,12,1)) -> 1766 | C9: =COUNTIFS(Dados_Brutos!A:A,">="&DATE(2024,1,1),Dados_Brutos!A:A,"<="&DATE(2025,12,31),Dados_Brutos!H:H,"Fora de Operação") -> 31 | D9: =COUNTIFS(Dados_Brutos!A:A,">="&$A9,Dados_Brutos!A:A,"<="&EOMONTH($A9,0),Dados_Brutos!K:K,"*Baixo*") -> 0 | E9: =COUNTIFS(Dados_Brutos!A:A,">="&$A9,Dados_Brutos!A:A,"<="&EOMONTH($A9,0),Dados_Brutos!K:K,"*Médio*") -> 0 | F9: =COUNTIFS(Dados_Brutos!A:A,">="&$A9,Dados_Brutos!A:A,"<="&EOMONTH($A9,0),Dados_Brutos!K:K,"*Alto*") -> 0 | G9: =B9*Config!$B$2 -> 2264356 | H9: =IF(B9>0, 30/B9, "Sem dados") -> 0.016987542 | I9: =IFERROR(AVERAGEIFS(Dados_Brutos!J:J, Dados_Brutos!A:A, ">="&A9, Dados_Brutos!A:A, "<="&EOMONTH(A9,0)),"-") -> - | J9: =(1-(SUMIFS(Dados_Brutos!J:J,Dados_Brutos!A:A,">="&DATE(2024,1,1),Dados_Brutos!A:A,"<="&DATE(2025,12,31))/(47*24*30))) -> 0.95537825
A10: 45469 | B10: =SUMIFS(Dados_Brutos!E:E,Dados_Brutos!A:A,">="&DATE(2024,1,1),Dados_Brutos!A:A,"<="&DATE(2025,12,1)) -> 1766 | C10: =COUNTIFS(Dados_Brutos!A:A,">="&DATE(2024,1,1),Dados_Brutos!A:A,"<="&DATE(2025,12,31),Dados_Brutos!H:H,"Fora de Operação") -> 31 | D10: =COUNTIFS(Dados_Brutos!A:A,">="&$A10,Dados_Brutos!A:A,"<="&EOMONTH($A10,0),Dados_Brutos!K:K,"*Baixo*") -> 0 | E10: =COUNTIFS(Dados_Brutos!A:A,">="&$A10,Dados_Brutos!A:A,"<="&EOMONTH($A10,0),Dados_Brutos!K:K,"*Médio*") -> 0 | F10: =COUNTIFS(Dados_Brutos!A:A,">="&$A10,Dados_Brutos!A:A,"<="&EOMONTH($A10,0),Dados_Brutos!K:K,"*Alto*") -> 0 | G10: =B10*Config!$B$2 -> 2264356 | H10: =IF(B10>0, 30/B10, "Sem dados") -> 0.016987542 | I10: =IFERROR(AVERAGEIFS(Dados_Brutos!J:J, Dados_Brutos!A:A, ">="&A10, Dados_Brutos!A:A, "<="&EOMONTH(A10,0)),"-") -> - | J10: =(1-(SUMIFS(Dados_Brutos!J:J,Dados_Brutos!A:A,">="&DATE(2024,1,1),Dados_Brutos!A:A,"<="&DATE(2025,12,31))/(47*24*30))) -> 0.95537825
A11: 45472 | B11: =SUMIFS(Dados_Brutos!E:E,Dados_Brutos!A:A,">="&DATE(2024,1,1),Dados_Brutos!A:A,"<="&DATE(2025,12,1)) -> 1766 | C11: =COUNTIFS(Dados_Brutos!A:A,">="&DATE(2024,1,1),Dados_Brutos!A:A,"<="&DATE(2025,12,31),Dados_Brutos!H:H,"Fora de Operação") -> 31 | D11: =COUNTIFS(Dados_Brutos!A:A,">="&$A11,Dados_Brutos!A:A,"<="&EOMONTH($A11,0),Dados_Brutos!K:K,"*Baixo*") -> 0 | E11: =COUNTIFS(Dados_Brutos!A:A,">="&$A11,Dados_Brutos!A:A,"<="&EOMONTH($A11,0),Dados_Brutos!K:K,"*Médio*") -> 0 | F11: =COUNTIFS(Dados_Brutos!A:A,">="&$A11,Dados_Brutos!A:A,"<="&EOMONTH($A11,0),Dados_Brutos!K:K,"*Alto*") -> 0 | G11: =B11*Config!$B$2 -> 2264356 | H11: =IF(B11>0, 30/B11, "Sem dados") -> 0.016987542 | I11: =IFERROR(AVERAGEIFS(Dados_Brutos!J:J, Dados_Brutos!A:A, ">="&A11, Dados_Brutos!A:A, "<="&EOMONTH(A11,0)),"-") -> - | J11: =(1-(SUMIFS(Dados_Brutos!J:J,Dados_Brutos!A:A,">="&DATE(2024,1,1),Dados_Brutos!A:A,"<="&DATE(2025,12,31))/(47*24*30))) -> 0.95537825
A12: 45475 | B12: =SUMIFS(Dados_Brutos!E:E,Dados_Brutos!A:A,">="&DATE(2024,1,1),Dados_Brutos!A:A,"<="&DATE(2025,12,1)) -> 1766 | C12: =COUNTIFS(Dados_Brutos!A:A,">="&DATE(2024,1,1),Dados_Brutos!A:A,"<="&DATE(2025,12,31),Dados_Brutos!H:H,"Fora de Operação") -> 31 | D12: =COUNTIFS(Dados_Brutos!A:A,">="&$A12,Dados_Brutos!A:A,"<="&EOMONTH($A12,0),Dados_Brutos!K:K,"*Baixo*") -> 1 | E12: =COUNTIFS(Dados_Brutos!A:A,">="&$A12,Dados_Brutos!A:A,"<="&EOMONTH($A12,0),Dados_Brutos!K:K,"*Médio*") -> 0 | F12: =COUNTIFS(Dados_Brutos!A:A,">="&$A12,Dados_Brutos!A:A,"<="&EOMONTH($A12,0),Dados_Brutos!K:K,"*Alto*") -> 0 | G12: =B12*Config!$B$2 -> 2264356 | H12: =IF(B12>0, 30/B12, "Sem dados") -> 0.016987542 | I12: =IFERROR(AVERAGEIFS(Dados_Brutos!J:J, Dados_Brutos!A:A, ">="&A12, Dados_Brutos!A:A, "<="&EOMONTH(A12,0)),"-") -> 12 | J12: =(1-(SUMIFS(Dados_Brutos!J:J,Dados_Brutos!A:A,">="&DATE(2024,1,1),Dados_Brutos!A:A,"<="&DATE(2025,12,31))/(47*24*30))) -> 0.95537825
A13: 45478 | B13: =SUMIFS(Dados_Brutos!E:E,Dados_Brutos!A:A,">="&DATE(2024,1,1),Dados_Brutos!A:A,"<="&DATE(2025,12,1)) -> 1766 | C13: =COUNTIFS(Dados_Brutos!A:A,">="&DATE(2024,1,1),Dados_Brutos!A:A,"<="&DATE(2025,12,31),Dados_Brutos!H:H,"Fora de Operação") -> 31 | D13: =COUNTIFS(Dados_Brutos!A:A,">="&$A13,Dados_Brutos!A:A,"<="&EOMONTH($A13,0),Dados_Brutos!K:K,"*Baixo*") -> 1 | E13: =COUNTIFS(Dados_Brutos!A:A,">="&$A13,Dados_Brutos!A:A,"<="&EOMONTH($A13,0),Dados_Brutos!K:K,"*Médio*") -> 0 | F13: =COUNTIFS(Dados_Brutos!A:A,">="&$A13,Dados_Brutos!A:A,"<="&EOMONTH($A13,0),Dados_Brutos!K:K,"*Alto*") -> 0 | G13: =B13*Config!$B$2 -> 2264356 | H13: =IF(B13>0, 30/B13, "Sem dados") -> 0.016987542 | I13: =IFERROR(AVERAGEIFS(Dados_Brutos!J:J, Dados_Brutos!A:A, ">="&A13, Dados_Brutos!A:A, "<="&EOMONTH(A13,0)),"-") -> 12 | J13: =(1-(SUMIFS(Dados_Brutos!J:J,Dados_Brutos!A:A,">="&DATE(2024,1,1),Dados_Brutos!A:A,"<="&DATE(2025,12,31))/(47*24*30))) -> 0.95537825
... A35: 45772 | B35: =SUMIFS(Dados_Brutos!E:E,Dados_Brutos!A:A,">="&DATE(2024,1,1),Dados_Brutos!A:A,"<="&DATE(2025,12,1)) -> 1766 | C35: =COUNTIFS(Dados_Brutos!A:A,">="&DATE(2024,1,1),Dados_Brutos!A:A,"<="&DATE(2025,12,31),Dados_Brutos!H:H,"Fora de Operação") -> 31 | D35: =COUNTIFS(Dados_Brutos!A:A,">="&$A35,Dados_Brutos!A:A,"<="&EOMONTH($A35,0),Dados_Brutos!K:K,"*Baixo*") -> 3 | E35: =COUNTIFS(Dados_Brutos!A:A,">="&$A35,Dados_Brutos!A:A,"<="&EOMONTH($A35,0),Dados_Brutos!K:K,"*Médio*") -> 0 | F35: =COUNTIFS(Dados_Brutos!A:A,">="&$A35,Dados_Brutos!A:A,"<="&EOMONTH($A35,0),Dados_Brutos!K:K,"*Alto*") -> 0 | G35: =B35*Config!$B$2 -> 2264356 | H35: =IF(B35>0, 30/B35, "Sem dados") -> 0.016987542 | I35: =IFERROR(AVERAGEIFS(Dados_Brutos!J:J, Dados_Brutos!A:A, ">="&A35, Dados_Brutos!A:A, "<="&EOMONTH(A35,0)),"-") -> 0 | J35: =(1-(SUMIFS(Dados_Brutos!J:J,Dados_Brutos!A:A,">="&DATE(2024,1,1),Dados_Brutos!A:A,"<="&DATE(2025,12,31))/(47*24*30))) -> 0.95537825

Sheet Carreiras_Criticas
A1: CARREIRA | B1: TURBINAS AFETADAS | C1: TOTAL SUBSTITUICOES | D1: CICLO MAIS AFETADO | E1: CLUSTER MAIS AFETADO | F1: PRIORIDADE MANUTENCAO | G1: CUSTO TOTAL | H1: INDICE FALHA
A2: 1 | B2: =COUNTIF(Dados_Brutos!#REF!,A2) -> #REF! | C2: =SUMIF(Dados_Brutos!#REF!,A2,Dados_Brutos!E:E) -> #REF! | D2: =IF(Tabela5[[#This Row],[TURBINAS AFETADAS]]>0, _xlfn.XLOOKUP(Tabela5[[#This Row],[CARREIRA]],Dados_Brutos!#REF!,Dados_Brutos!G:G,"Sem dados",0,-1),"Sem dados") -> #REF! | E2: =IF(Tabela5[[#This Row],[TURBINAS AFETADAS]]>0, _xlfn.XLOOKUP(Tabela5[[#This Row],[CARREIRA]],Dados_Brutos!#REF!,Dados_Brutos!C:C,"Sem dados",0,-1),"Sem dados") -> #REF! | F2: =IF(AND(B2>5,C2>20),"🔴 ALTA",IF(AND(B2>3,C2>10),"🟡 MÉDIA","🟢 BAIXA")) -> #REF! | G2: =C2*Config!$B$2 -> #REF! | H2: =IF(B2>0,C2/B2,0) -> #REF!
A3: 2 | B3: =COUNTIF(Dados_Brutos!#REF!,A3) -> #REF! | C3: =SUMIF(Dados_Brutos!#REF!,A3,Dados_Brutos!E:E) -> #REF! | D3: =IF(Tabela5[[#This Row],[TURBINAS AFETADAS]]>0, _xlfn.XLOOKUP(Tabela5[[#This Row],[CARREIRA]],Dados_Brutos!#REF!,Dados_Brutos!G:G,"Sem dados",0,-1),"Sem dados") -> #REF! | E3: =IF(Tabela5[[#This Row],[TURBINAS AFETADAS]]>0, _xlfn.XLOOKUP(Tabela5[[#This Row],[CARREIRA]],Dados_Brutos!#REF!,Dados_Brutos!C:C,"Sem dados",0,-1),"Sem dados") -> #REF! | F3: =IF(AND(B3>5,C3>20),"🔴 ALTA",IF(AND(B3>3,C3>10),"🟡 MÉDIA","🟢 BAIXA")) -> #REF! | G3: =C3*Config!$B$2 -> #REF! | H3: =IF(B3>0,C3/B3,0) -> #REF!
A4: 3 | B4: =COUNTIF(Dados_Brutos!#REF!,A4) -> #REF! | C4: =SUMIF(Dados_Brutos!#REF!,A4,Dados_Brutos!E:E) -> #REF! | D4: =IF(Tabela5[[#This Row],[TURBINAS AFETADAS]]>0, _xlfn.XLOOKUP(Tabela5[[#This Row],[CARREIRA]],Dados_Brutos!#REF!,Dados_Brutos!G:G,"Sem dados",0,-1),"Sem dados") -> #REF! | E4: =IF(Tabela5[[#This Row],[TURBINAS AFETADAS]]>0, _xlfn.XLOOKUP(Tabela5[[#This Row],[CARREIRA]],Dados_Brutos!#REF!,Dados_Brutos!C:C,"Sem dados",0,-1),"Sem dados") -> #REF! | F4: =IF(AND(B4>5,C4>20),"🔴 ALTA",IF(AND(B4>3,C4>10),"🟡 MÉDIA","🟢 BAIXA")) -> #REF! | G4: =C4*Config!$B$2 -> #REF! | H4: =IF(B4>0,C4/B4,0) -> #REF!
A5: 4 | B5: =COUNTIF(Dados_Brutos!#REF!,A5) -> #REF! | C5: =SUMIF(Dados_Brutos!#REF!,A5,Dados_Brutos!E:E) -> #REF! | D5: =IF(Tabela5[[#This Row],[TURBINAS AFETADAS]]>0, _xlfn.XLOOKUP(Tabela5[[#This Row],[CARREIRA]],Dados_Brutos!#REF!,Dados_Brutos!G:G,"Sem dados",0,-1),"Sem dados") -> #REF! | E5: =IF(Tabela5[[#This Row],[TURBINAS AFETADAS]]>0, _xlfn.XLOOKUP(Tabela5[[#This Row],[CARREIRA]],Dados_Brutos!#REF!,Dados_Brutos!C:C,"Sem dados",0,-1),"Sem dados") -> #REF! | F5: =IF(AND(B5>5,C5>20),"🔴 ALTA",IF(AND(B5>3,C5>10),"🟡 MÉDIA","🟢 BAIXA")) -> #REF! | G5: =C5*Config!$B$2 -> #REF! | H5: =IF(B5>0,C5/B5,0) -> #REF!
A6: 5 | B6: =COUNTIF(Dados_Brutos!#REF!,A6) -> #REF! | C6: =SUMIF(Dados_Brutos!#REF!,A6,Dados_Brutos!E:E) -> #REF! | D6: =IF(Tabela5[[#This Row],[TURBINAS AFETADAS]]>0, _xlfn.XLOOKUP(Tabela5[[#This Row],[CARREIRA]],Dados_Brutos!#REF!,Dados_Brutos!G:G,"Sem dados",0,-1),"Sem dados") -> #REF! | E6: =IF(Tabela5[[#This Row],[TURBINAS AFETADAS]]>0, _xlfn.XLOOKUP(Tabela5[[#This Row],[CARREIRA]],Dados_Brutos!#REF!,Dados_Brutos!C:C,"Sem dados",0,-1),"Sem dados") -> #REF! | F6: =IF(AND(B6>5,C6>20),"🔴 ALTA",IF(AND(B6>3,C6>10),"🟡 MÉDIA","🟢 BAIXA")) -> #REF! | G6: =C6*Config!$B$2 -> #REF! | H6: =IF(B6>0,C6/B6,0) -> #REF!
